# 异常处理

## 一 defer 延迟执行

### 1.1 defer延迟执行修饰符

Go语言提供的defer机制，可以让开发者在创建资源(比如:数据库连接、文件句柄、锁等) 后，能够及时释放资源：

```go
func main() {
	//当执行到defer语句时，暂不执行，会将defer后的语句压入到独立的栈中,当函数执行完毕后，再从该栈按照先入后出的方式出栈执行
	defer fmt.Println("defer1...")
	defer fmt.Println("defer2...")
	fmt.Println("main...")
}
```

上述代码执行结果：

```
main...
defer2...
defer1...
```

`defer`将语句放入到栈时，也会将相关的值拷贝同时入栈:

```go
func main() {
	num := 0
	defer fmt.Println("defer中：num=", num)
	num = 3
	fmt.Println("main中：num=",num)
}
```

输出结果：

```
main中：num= 3
defer中：num= 0
```

### 1.2 defer最佳实践 

案例一：defer处理资源  

没有使用defer时打开文件处理代码：

```go
f,err := os.Open(file)
if err != nil {
	return 0
}

info,err := f.Stat()
if err != nil {
	f.Close()
	return 0
}

f.Close()
return 0;

```

使用defer优化：

```go
f,err := os.Open(file)
if err != nil {
	return 0
}

defer f.Close()

info,err := f.Stat()

if err != nil {
	// f.Close()			//这句已经不需要了
	return 0
}

//后续一系列文件操作后执行关闭
// f.Close()			//这句已经不需要了
return 0;
```


案例二：并发使用map的函数。  

无defer代码：

```go
var (
	mutex sync.Mutex
	testMap = make(map[string]int)
)
func getMapValue(key string) int {
	mutex.Lock()						//对共享资源加锁
	value := testMap[key]
	mutex.Unlock()
	return value
}
```

上述案例是很常见的对并发map执行加锁执行的安全操作，使用defer可以对上述语义进行简化：

```go
var (
	mutex sync.Mutex
	testMap = make(map[string]int)
)
func getMapValue(key string) int {
	mutex.Lock()						//对共享资源加锁
	defer mutex.Unlock()
	return testMap[key]
}
```

### 1.3 defer无法处理全局资源

使用defer语句, 可以方便地组合函数/闭包和资源对象，即使panic时，defer也能保证资源的正确释放。但是上述案例都是在局部使用和释放资源，如果资源的生命周期很长， 而且可能被多个模块共享和随意传递的话，defer语句就不好处理了。   

Go的`runtime`包的`func SetFinalize(x, f interface{})`函数可以提供类似C++析构函数的机制。  

示例：包装一个文件对象，在没有人使用的时候能够自动关闭。

```go
type MyFile struct {
	f *os.File
}

func NewFile(name string) (&MyFile, error){
	file, err := os.Open(name)
	if err != nil {
		return nil, err
	}
	runtime.SetFinalizer(file, file.f.Close)
	return &MyFile{f: file}, nil
}
```

在使用`runtime.SetFinalizer`时, 需要注意的地方是尽量要用指针访问内部资源，这样的话, 即使`*MyFile`对象忘记释放, 或者是被别的对象无意中覆盖, 也可以保证内部的文件资源可以正确释放。

## 一、Error 错误 :crossed_swords:

**Go提供了两种创建error的方法：**

+ ①：errors.New  使用errors.New 可返回一个错误信息

+ ②：fmt.Errorf

**约定最后返回值为 error 类型，一般常见于第二个返回值，这是一个约定俗成的习惯。**

### 基本使用

```go
import (
    "errors"
    "fmt"
    "log"
)

// 
func Hello(name string) (string, error) {
    if name == "" {
        // return "", fmt.Errorf("empty name")
        return "", errors.New("empty name")      // 返回一个错误信息
    }
    
    message := fmt.Sprintf("Hi, %v. Welcome!", name)
    return message, nil  // 返回nil，说明没有异常
}

func main() {
    message, err := Hello("")
    //如果不为nil，说明异常，要做异常
    if err != nil {
        log.Fatal(err)
    }

    fmt.Println(message)
}
```

### 自定义错误

```go
package main

import (
	"fmt"
)

//声明一种解析错误
type ParseError struct {
	Filename string
	Line int
}

//实现error接口，返回错误描述
func (e *ParseError) Error() string {
	return fmt.Sprintf("%s:%d", e.Filename, e.Line)
}

//创建一些解析错误
func newParseError(filename string, line int) error {
	return &ParseError{filename, line}
}

func main() {
	var e error
	e = newParseError("main.go", 1)
	fmt.Println(e.Error())

	switch detail := e.(type) {
	case *ParseError:
		fmt.Printf("Filename: %s Line:%d \n", detail.Filename, detail.Line)
	default: 
		fmt.Println("other error")
	}
}
```

## 二、panic 宕机

### 基本使用

#### panic 宕机

> panic是一个Go内置函数，它用来停止当前常规控制流并启动panicking（运行时恐慌）过程。

panic的触发有两种：

+ ①：在运行时遇到错误触发 panic，比如越界访问数组，不相同类型的变量强制类型转换等

+ ②：通过显式直接调用 panic 函数触发 panic

func panic(v interface{}) panic  panic函数接收一个interface{}空接口类型的参数，也就是说，panic函数可以接收一个任意类型的参数。　　

```go
func test() {
    // 显式调用panic
    panic("panic error!")
}
```

通常，不会去捕获运行时 panic，发生 panic 异常，直接让程序崩溃即可，及时根据 panic 提供的信息，修复异常。但是，一些情况下，我们还是需要捕获 panic，比如在程序发生 panic 异常时，释放资源。比如关闭文件或者释放锁

Go中可以抛出一个panic的异常，然后在defer中通过recover() 捕获这个异常，将 panic 错误写入日志文件，将程序恢复正常执行

#### recover 宕机恢复

> 调用recover() 函数可以捕获panic

panic和defer的组合：

- 有panic没有recover，程序宕机
- 有panic也有recover，程序不会宕机，执行完对应的defer后，从宕机点退出当前函数后继续执行

```go
func a() int{
    i:=0
    return 10/i
}

func main() {
    // 捕获处理panic
    defer func(){
        //设置recover拦截错误信息
        if r := recover(); r != nil {
            fmt.Printf("panic recover:%s", r)
        }
    }()
    
    // 触发panic
    a()
    // 不会再执行
    fmt.Println("123")
}
```

### 实现类似 try catch 的异常处理

```go
/*
实现类似try catch处理，后续代码可正常执行
fun() 可能触发panic的函数
hander() panic处理函数
*/
func Try(fun func(), handler func(interface{})) {
    defer func() {
        if err := recover(); err != nil {
            handler(err)
        }
    }()
    fun()
}

func main() {
    Try(func() {
        //
        panic("test panic")
    }, func(err interface{}) {
        //
        fmt.Println(err)
    })

    // 后续代码可继续执行
    fmt.Println("panic handled")
}
```

### error和panic区别

error一般是程序员可预知的，会进行合适的处理，例如检测输入是否合法等

而panic是程序员无法预知的异常，例如空指针或数组越界等, panic 导致的后果非常严重，会导致程序崩溃

## 三、throw

这个错误类型，在用户侧是没法主动调用的，均为 Go 底层自行调用的，像是大家常见的 map 并发读写，就是由此触发

参考:

+ [Golang错误处理最佳实践 (yuque.com)](https://www.yuque.com/kolo7/olgrzk/8a80a18b51dc0b3b03cf13ba33aceec3)